<?xml version="1.0" encoding="utf-8" ?>
<!-- This URDF was automatically created by SolidWorks to URDF Exporter! Originally created by Stephen Brawner (brawner@gmail.com) 
     Commit Version: 1.5.1-0-g916b5db  Build Version: 1.5.7152.31018
     For more information, please see http://wiki.ros.org/sw_urdf_exporter -->
<robot name="mob_manip" xmlns:xacro="http://ros.org/wiki/xacro">
<xacro:include filename="$(find robotiq_85_description)/urdf/robotiq_85_gripper.urdf.xacro" />
    <link name="base_link">
<!--This is the base link of the mobile manipulator -->        
<inertial>
            <origin xyz="0.513058360875689 -0.117717976987648 0.356205769731144" rpy="0 0 0" />
            <mass value="15.72484623513" />
            <inertia ixx="1.08796670365496" ixy="-0.0136266724932048" ixz="-2.40927967886263E-05" iyy="1.70753131675544" iyz="-3.25212662415233E-06" izz="0.807688361226205" />
        </inertial>

        <visual>
            <origin xyz="0 0 0" rpy="0 0 0" />
            <geometry>
                <mesh filename="package://mob_manip/meshes/base_link.STL" />
            </geometry>
            <material name="">
                <color rgba="0.792156862745098 0.819607843137255 0.933333333333333 1" />
            </material>
        </visual>
        <collision>
            <origin xyz="0 0 0" rpy="0 0 0" />
            <geometry>
                <mesh filename="package://mob_manip/meshes/base_link.STL" />
            </geometry>
        </collision>
    </link>


<!-- Kinect Sensor -->
<link name="camera_link">
    <collision>
      <origin xyz="0 0 0" rpy="0 0 0"/>
      <geometry>
        <box size="0.073000 0.276000 0.072000"/>
      </geometry>
    </collision>

    <visual>
      <origin xyz="0 0 0" rpy="0 0 0"/>
      <geometry>
        <mesh filename="package://mob_manip/meshes/kinect.dae" />
      </geometry>
    </visual>

    <inertial>
      <mass value="0.1" />
      <origin xyz="0 0 0" rpy="0 0 0"/>
      <inertia ixx="1e-6" ixy="0" ixz="0" iyy="1e-6" iyz="0" izz="1e-6" />
    </inertial>
    </link>
    <joint name="kinect_joint" type="fixed">
        <origin xyz="0.280 -0.332 0.05" rpy="0 0 3.12" />
        <parent link="base_link" />
        <child link="camera_link" />
        <axis xyz="0 1 0" />
    </joint>

    <joint name="cameraLeft_depth_joint" type="fixed">
    <origin xyz="0 0 0" rpy="-1.57 0 -1.57 "/>
    <parent link="camera_link"/>
    <child link="cameraLeft_depth_link"/>
    </joint>

    <link name="cameraLeft_depth_link"></link>



<!--w1,w2,w3,w4 are the 4 wheels of mobile base -->
    <link name="w1">
        
<inertial>
            <origin xyz="2.77555756156289E-17 0 -0.0375" rpy="0 0 0" />
            <mass value="0.801459555838926" />
            <inertia ixx="0.0012625171681338" ixy="2.71050543121376E-20" ixz="-1.57178524730168E-21" iyy="0.0012625171681338" iyz="-5.11354914277531E-21" izz="0.00223754179292522" />
        </inertial>

        <visual>
            <origin xyz="0 0 0" rpy="0 0 0" />
            <geometry>
                <mesh filename="package://mob_manip/meshes/w1.STL" />
            </geometry>
            <material name="">
                <color rgba="0.792156862745098 0.819607843137255 0.933333333333333 1" />
            </material>
        </visual>
        <collision>
            <origin xyz="0 0 0" rpy="0 0 0" />
            <geometry>
                <mesh filename="package://mob_manip/meshes/w1.STL" />
            </geometry>
        </collision>
    </link>
    <joint name="l1" type="continuous">
        <origin xyz="0.88574 0.03129 -0.195" rpy="1.5708 -1.2577 0" />
        <parent link="base_link" />
        <child link="w1" />
        <axis xyz="0 0 -1" />
    </joint>
    <link name="w2">
        
<inertial>
            <origin xyz="0 0 -0.0375" rpy="0 0 0" />
            <mass value="0.801459555838926" />
            <inertia ixx="0.00126251716813379" ixy="1.35525271560688E-19" ixz="1.51573800403417E-20" iyy="0.0012625171681338" iyz="-8.83569894135245E-21" izz="0.00223754179292522" />
        </inertial>

        <visual>
            <origin xyz="0 0 0" rpy="0 0 0" />
            <geometry>
                <mesh filename="package://mob_manip/meshes/w2.STL" />
            </geometry>
            <material name="">
                <color rgba="0.792156862745098 0.819607843137255 0.933333333333333 1" />
            </material>
        </visual>
        <collision>
            <origin xyz="0 0 0" rpy="0 0 0" />
            <geometry>
                <mesh filename="package://mob_manip/meshes/w2.STL" />
            </geometry>
        </collision>
    </link>
    <joint name="l2" type="continuous">
        <origin xyz="0.12574 0.03129 -0.17" rpy="1.5708 1.1431 0" />
        <parent link="base_link" />
        <child link="w2" />
        <axis xyz="0 0 -1" />
    </joint>
    <link name="w3">
        
<inertial>
            <origin xyz="-1.1102E-16 -2.7756E-17 0.0375" rpy="0 0 0" />
            <mass value="0.80146" />
            <inertia ixx="0.0012625" ixy="-2.7105E-20" ixz="1.1975E-21" iyy="0.0012625" iyz="-2.156E-22" izz="0.0022375" />
        </inertial>

        <visual>
            <origin xyz="0 0 0" rpy="0 0 0" />
            <geometry>
                <mesh filename="package://mob_manip/meshes/w3.STL" />
            </geometry>
            <material name="">
                <color rgba="0.79216 0.81961 0.93333 1" />
            </material>
        </visual>
        <collision>
            <origin xyz="0 0 0" rpy="0 0 0" />
            <geometry>
                <mesh filename="package://mob_manip/meshes/w3.STL" />
            </geometry>
        </collision>
    </link>
    <joint name="r1" type="continuous">
        <origin xyz="0.88574 -0.74371 -0.195" rpy="1.5708 0.18318 0" />
        <parent link="base_link" />
        <child link="w3" />
        <axis xyz="0 0 -1" />
    </joint>
    <link name="w4">
        
<inertial>
            <origin xyz="0 0 0.0375" rpy="0 0 0" />
            <mass value="0.801459555838927" />
            <inertia ixx="0.0012625171681338" ixy="-5.9292306307801E-21" ixz="3.43751316972066E-21" iyy="0.0012625171681338" iyz="-3.3244993051953E-22" izz="0.00223754179292522" />
        </inertial>

        <visual>
            <origin xyz="0 0 0" rpy="0 0 0" />
            <geometry>
                <mesh filename="package://mob_manip/meshes/w4.STL" />
            </geometry>
            <material name="">
                <color rgba="0.792156862745098 0.819607843137255 0.933333333333333 1" />
            </material>
        </visual>
        <collision>
            <origin xyz="0 0 0" rpy="0 0 0" />
            <geometry>
                <mesh filename="package://mob_manip/meshes/w4.STL" />
            </geometry>
        </collision>
    </link>
    <joint name="r2" type="continuous">
        <origin xyz="0.12574 -0.74371 -0.17" rpy="1.5708 -0.011372 0" />
        <parent link="base_link" />
        <child link="w4" />
        <axis xyz="0 0 -1" />
    </joint>
<!-- Link1,Link2,Link3,Link4 are the links of manipulator and Link5 is the end-effector(screw dricer) -->
    <link name="Link1">
        
<inertial>
            <origin xyz="1.11022302462516E-16 0.05747068219005 -0.0129024755809186" rpy="0 0 0" />
            <mass value="0.221199667920846" />
            <inertia ixx="0.000587681659431752" ixy="-1.21972744404619E-19" ixz="-1.79740391407363E-18" iyy="0.00117861748383056" iyz="8.04398901867666E-05" izz="0.00114651902699794" />
        </inertial>

        <visual>
            <origin xyz="0 0 0" rpy="0 0 0" />
            <geometry>
                <mesh filename="package://mob_manip/meshes/Link1.STL" />
            </geometry>
            <material name="">
                <color rgba="0.792156862745098 0.819607843137255 0.933333333333333 1" />
            </material>
        </visual>
        <collision>
            <origin xyz="0 0 0" rpy="0 0 0" />
            <geometry>
                <mesh filename="package://mob_manip/meshes/Link1.STL" />
            </geometry>
        </collision>
    </link>
    <joint name="j1" type="continuous">
        <origin xyz="0.66574 -0.35621 0.005" rpy="1.5708 0 -1.6133" />
        <parent link="base_link" />
        <child link="Link1" />
        <axis xyz="0 1 0" />
    </joint>
    <link name="Link2">
        
<inertial>
            <origin xyz="0.0034038 0.005382 -0.18905" rpy="0 0 0" />
            <mass value="0.15671" />
            <inertia ixx="0.0023831" ixy="-4.1188E-08" ixz="1.4468E-06" iyy="0.0027923" iyz="6.6915E-05" izz="0.00044373" />
        </inertial>

        <visual>
            <origin xyz="0 0 0" rpy="0 0 0" />
            <geometry>
                <mesh filename="package://mob_manip/meshes/Link2.STL" />
            </geometry>
            <material name="">
                <color rgba="0.79216 0.81961 0.93333 1" />
            </material>
        </visual>
        <collision>
            <origin xyz="0 0 0" rpy="0 0 0" />
            <geometry>
                <mesh filename="package://mob_manip/meshes/Link2.STL" />
            </geometry>
        </collision>
    </link>
    <joint name="j2" type="revolute">
        <origin xyz="0 0.085 -0.088586" rpy="0.87206 0 0" />
        <parent link="Link1" />
        <child link="Link2" />
        <axis xyz="1 0 0" />
        <limit lower="-1.5708" upper="1.5708" effort="50" velocity="100" />
    </joint>
    <link name="Link3">
        
<inertial>
            <origin xyz="-9.26428305997318E-05 0.000750789555956623 -0.104832677638645" rpy="0 0 0" />
            <mass value="0.0436215921712802" />
            <inertia ixx="0.000169717854371362" ixy="-3.57847474225765E-08" ixz="-3.62157682604577E-06" iyy="0.000229282201716468" iyz="-5.19226647774999E-07" izz="6.54024268733061E-05" />
        </inertial>

        <visual>
            <origin xyz="0 0 0" rpy="0 0 0" />
            <geometry>
                <mesh filename="package://mob_manip/meshes/Link3.STL" />
            </geometry>
            <material name="">
                <color rgba="0.792156862745098 0.819607843137255 0.933333333333333 1" />
            </material>
        </visual>
        <collision>
            <origin xyz="0 0 0" rpy="0 0 0" />
            <geometry>
                <mesh filename="package://mob_manip/meshes/Link3.STL" />
            </geometry>
        </collision>
    </link>
    <joint name="j3" type="revolute">
        <origin xyz="0 0.010603 -0.37242" rpy="-0.54206 0 0" />
        <parent link="Link2" />
        <child link="Link3" />
        <axis xyz="1 0 0" />
        <limit lower="-1.5708" upper="1.5708" effort="50" velocity="100" />
    </joint>
    <link name="Link4">
        
<inertial>
            <origin xyz="1.1102E-16 0.06315 0.003" rpy="0 0 0" />
            <mass value="0.026823" />
            <inertia ixx="7.5437E-05" ixy="-3.3408E-20" ixz="-1.8127E-19" iyy="4.3404E-05" iyz="-2.8386E-19" izz="3.6133E-05" />
        </inertial>

        <visual>
            <origin xyz="0 0 0" rpy="0 0 0" />
            <geometry>
                <mesh filename="package://mob_manip/meshes/Link4.STL" />
            </geometry>
            <material name="">
                <color rgba="0.79216 0.81961 0.93333 1" />
            </material>
        </visual>
        <collision>
            <origin xyz="0 0 0" rpy="0 0 0" />
            <geometry>
                <mesh filename="package://mob_manip/meshes/Link4.STL" />
            </geometry>
        </collision>
    </link>
    <joint name="j4" type="revolute">
        <origin xyz="0 0 -0.18082" rpy="-1.5708 0.42088 -1.5708" />
        <parent link="Link3" />
        <child link="Link4" />
        <axis xyz="0 0 1" />
        <limit lower="-1.5708" upper="1.5708" effort="50" velocity="100" />
    </joint>
    <!-- ######################################################################################################################################################################### -->
    <joint name="gripper_base_joint" type="fixed">
            <parent link="Link4"/>
            <child link="gripper_base_link"/>
            <origin rpy="4.8 0 -4.8" xyz="0.02 0.14 0.0"/>
            <xacro:insert_block name="origin"/>
        </joint>
        
        <link name="gripper_base_link">
            <visual>
                <geometry>
                    <mesh filename="package://robotiq_85_description/meshes/visual/robotiq_85_base_link.dae"/>
                </geometry>
            </visual>
            <collision>
                <geometry>
                    <mesh filename="package://robotiq_85_description/meshes/collision/robotiq_85_base_link.stl"/>
                </geometry>
            </collision>
            <inertial>
                <mass value="0.636951" />
                <origin xyz="0.0 0.0 0.0" />
                <inertia ixx = "0.000380" ixy = "0.000000" ixz = "0.000000"
                         iyx = "0.000000" iyy = "0.001110" iyz = "0.000000"
                         izx = "0.000000" izy = "0.000000" izz = "0.001171" />
            </inertial>
        </link>

        <gazebo reference="gripper_base_link">
            <implicitSpringDamper>1</implicitSpringDamper>
            <mu1>100000</mu1>
            <mu2>100000</mu2>
            <kp>100000000.0</kp>
            <kd>1.0</kd>
        </gazebo>   

        <joint name="gripper_finger1_joint" type="revolute">
            <parent link="gripper_base_link"/>
            <child link="gripper_finger1_knuckle_link"/>
            <axis xyz="0 0 1"/>
            <origin rpy="3.14 0.0 0.0" xyz="0.05490451627 0.03060114443 0.0"/>
            <limit lower="0.0" upper="0.804" velocity="2.0" effort="1000"/>
        </joint>

        <joint name="gripper_finger2_joint" type="revolute">
            <parent link="gripper_base_link"/>
            <child link="gripper_finger2_knuckle_link"/>
            <axis xyz="0 0 1"/>
            <origin rpy="0.0 0.0 0.0" xyz="0.05490451627 -0.03060114443 0.0"/>
            <limit lower="-3.14" upper="3.14" velocity="100.0" effort="1000"/>
            <mimic joint="gripper_finger1_joint"/>
        </joint>

        <link name="gripper_finger1_knuckle_link">
            <visual>
                <geometry>
                    <mesh filename="package://robotiq_85_description/meshes/visual/robotiq_85_knuckle_link.dae"/>
                </geometry>
            </visual>
            <collision>
                <geometry>
                    <mesh filename="package://robotiq_85_description/meshes/collision/robotiq_85_knuckle_link.stl"/>
                </geometry>
            </collision>
            <inertial>
                <mass value="0.018491" />
                <origin xyz="0.0 0.0 0.0" />
                <inertia ixx = "0.000009" ixy = "-0.000001" ixz = "0.000000"
                         iyx = "-0.000001" iyy = "0.000001" iyz = "0.000000"
                         izx = "0.000000" izy = "0.000000" izz = "0.000010" />
            </inertial>
        </link>
        
        <gazebo reference="gripper_finger1_knuckle_link">
            <implicitSpringDamper>1</implicitSpringDamper>
            <mu1>100000</mu1>
            <mu2>100000</mu2>
            <kp>100000000.0</kp>
            <kd>1.0</kd>
        </gazebo>   

        <link name="gripper_finger2_knuckle_link">
            <visual>
                <geometry>
                    <mesh filename="package://robotiq_85_description/meshes/visual/robotiq_85_knuckle_link.dae"/>
                </geometry>
            </visual>
            <collision>
                <geometry>
                    <mesh filename="package://robotiq_85_description/meshes/collision/robotiq_85_knuckle_link.stl"/>
                </geometry>
            </collision>
            <inertial>
                <mass value="0.018491" />
                <origin xyz="0.0 0.0 0.0" />
                <inertia ixx = "0.000009" ixy = "-0.000001" ixz = "0.000000"
                         iyx = "-0.000001" iyy = "0.000001" iyz = "0.000000"
                         izx = "0.000000" izy = "0.000000" izz = "0.000010" />
            </inertial>
        </link>

        <gazebo reference="gripper_finger2_knuckle_link">
            <implicitSpringDamper>1</implicitSpringDamper>
            <mu1>100000</mu1>
            <mu2>100000</mu2>
            <kp>100000000.0</kp>
            <kd>1.0</kd>
        </gazebo> 

        <joint name="gripper_finger1_finger_joint" type="fixed">
            <parent link="gripper_finger1_knuckle_link"/>
            <child link="gripper_finger1_finger_link"/>
            <origin xyz="-0.00408552455 -0.03148604435 0.0" rpy="0 0 0" />
        </joint>

        <joint name="gripper_finger2_finger_joint" type="fixed">
            <parent link="gripper_finger2_knuckle_link"/>
            <child link="gripper_finger2_finger_link"/>
            <origin xyz="-0.00408552455 -0.03148604435 0.0" rpy="0 0 0" />
        </joint>

        <link name="gripper_finger1_finger_link">
            <visual>
                <geometry>
                    <mesh filename="package://robotiq_85_description/meshes/visual/robotiq_85_finger_link.dae"/>
                </geometry>
            </visual>
            <collision>
                <geometry>
                    <mesh filename="package://robotiq_85_description/meshes/collision/robotiq_85_finger_link.stl"/>
                </geometry>
            </collision>
            <inertial>
                <mass value="0.027309" />
                <origin xyz="0.0 0.0 0.0" />
                <inertia ixx = "0.000003" ixy = "-0.000002" ixz = "0.000000"
                         iyx = "-0.000002" iyy = "0.000021" iyz = "0.000000"
                         izx = "0.000000" izy = "0.000000" izz = "0.000020" />
            </inertial>
        </link>

        <gazebo reference="gripper_finger1_finger_link">
            <implicitSpringDamper>1</implicitSpringDamper>
            <mu1>100000</mu1>
            <mu2>100000</mu2>
            <kp>100000000.0</kp>
            <kd>1.0</kd>
        </gazebo>  

        <link name="gripper_finger2_finger_link">
            <visual>
                <geometry>
                    <mesh filename="package://robotiq_85_description/meshes/visual/robotiq_85_finger_link.dae"/>
                </geometry>
            </visual>
            <collision>
                <geometry>
                    <mesh filename="package://robotiq_85_description/meshes/collision/robotiq_85_finger_link.stl"/>
                </geometry>
            </collision>
            <inertial>
                <mass value="0.027309" />
                <origin xyz="0.0 0.0 0.0" />
                <inertia ixx = "0.000003" ixy = "-0.000002" ixz = "0.000000"
                         iyx = "-0.000002" iyy = "0.000021" iyz = "0.000000"
                         izx = "0.000000" izy = "0.000000" izz = "0.000020" />
            </inertial>
        </link>

        <gazebo reference="gripper_finger2_finger_link">
            <implicitSpringDamper>1</implicitSpringDamper>
            <mu1>100000</mu1>
            <mu2>100000</mu2>
            <kp>100000000.0</kp>
            <kd>1.0</kd>
        </gazebo>  

        <joint name="gripper_finger1_inner_knuckle_joint" type="continuous">
            <parent link="gripper_base_link"/>
            <child link="gripper_finger1_inner_knuckle_link"/>
            <axis xyz="0 0 1"/>
            <origin xyz="0.06142 0.0127 0" rpy="3.14 0.0 0.0" />
            <limit lower="-3.14" upper="3.14" velocity="100.0" effort="0.1"/>
            <mimic joint="gripper_finger1_joint" offset="0"/>
        </joint>

        <joint name="gripper_finger2_inner_knuckle_joint" type="continuous">
            <parent link="gripper_base_link"/>
            <child link="gripper_finger2_inner_knuckle_link"/>
            <axis xyz="0 0 1"/>
            <origin xyz="0.06142 -0.0127 0" rpy="0 0 0"/>
            <limit lower="-3.14" upper="3.14" velocity="100.0" effort="0.1"/>
            <mimic joint="gripper_finger1_joint" offset="0"/>
        </joint>

        <link name="gripper_finger1_inner_knuckle_link">
            <visual>
                <geometry>
                    <mesh filename="package://robotiq_85_description/meshes/visual/robotiq_85_inner_knuckle_link.dae"/>
                </geometry>
            </visual>
            <collision>
                <geometry>
                    <mesh filename="package://robotiq_85_description/meshes/collision/robotiq_85_inner_knuckle_link.stl"/>
                </geometry>
            </collision>
            <inertial>
                <mass value="0.029951" />
                <origin xyz="0.0 0.0 0.0" />
                <inertia ixx = "0.000039" ixy = "0.000000" ixz = "0.000000"
                         iyx = "0.000000" iyy = "0.000005" iyz = "0.000000"
                         izx = "0.000000" izy = "0.000000" izz = "0.000035" />
            </inertial>
        </link>

        <gazebo reference="gripper_finger1_inner_knuckle_link">
            <implicitSpringDamper>1</implicitSpringDamper>
            <mu1>100000</mu1>
            <mu2>100000</mu2>
            <kp>100000000.0</kp>
            <kd>1.0</kd>
        </gazebo> 
        
        <link name="gripper_finger2_inner_knuckle_link">
            <visual>
                <geometry>
                    <mesh filename="package://robotiq_85_description/meshes/visual/robotiq_85_inner_knuckle_link.dae"/>
                </geometry>
            </visual>
            <collision>
                <geometry>
                    <mesh filename="package://robotiq_85_description/meshes/collision/robotiq_85_inner_knuckle_link.stl"/>
                </geometry>
            </collision>
            <inertial>
                <mass value="0.029951" />
                <origin xyz="0.0 0.0 0.0" />
                <inertia ixx = "0.000039" ixy = "0.000000" ixz = "0.000000"
                         iyx = "0.000000" iyy = "0.000005" iyz = "0.000000"
                         izx = "0.000000" izy = "0.000000" izz = "0.000035" />
            </inertial>
        </link>

        <gazebo reference="gripper_finger2_inner_knuckle_link">
            <implicitSpringDamper>1</implicitSpringDamper>
            <mu1>100000</mu1>
            <mu2>100000</mu2>
            <kp>100000000.0</kp>
            <kd>1.0</kd>
        </gazebo> 

        <joint name="gripper_finger1_finger_tip_joint" type="continuous">
            <parent link="gripper_finger1_inner_knuckle_link"/>
            <child link="gripper_finger1_finger_tip_link"/>
            <axis xyz="0 0 1"/>
            <origin xyz="0.04303959807 -0.03759940821 0.0" rpy="0.0 0.0 0.0"/>
            <limit lower="-3.14" upper="3.14" velocity="100.0" effort="0.1"/>
            <mimic joint="gripper_finger1_joint" multiplier="-1"/>
        </joint>

        <joint name="gripper_finger2_finger_tip_joint" type="continuous">
            <parent link="gripper_finger2_inner_knuckle_link"/>
            <child link="gripper_finger2_finger_tip_link"/>
            <axis xyz="0 0 1"/>
            <origin rpy="0.0 0.0 0.0" xyz="0.04303959807 -0.03759940821  0.0"/>
            <limit lower="-3.14" upper="3.14" velocity="100.0" effort="0.1"/>
            <mimic joint="gripper_finger1_joint" multiplier="-1"/>
        </joint>


        <link name="gripper_finger1_finger_tip_link">
            <visual>
                <geometry>
                    <mesh filename="package://robotiq_85_description/meshes/visual/robotiq_85_finger_tip_link.dae"/>
                </geometry>
            </visual>
            <collision>
                <geometry>
                    <mesh filename="package://robotiq_85_description/meshes/collision/robotiq_85_finger_tip_link.stl"/>
                </geometry>
            </collision>
            <inertial>
                <mass value="0.019555" />
                <origin xyz="0.0 0.0 0.0" />
                <inertia ixx = "0.000002" ixy = "0.000000" ixz = "0.000000"
                         iyx = "0.000000" iyy = "0.000005" iyz = "0.000000"
                         izx = "0.000000" izy = "0.000000" izz = "0.000006" />
            </inertial>
        </link> 
        
        <gazebo reference="gripper_finger1_finger_tip_link">
            <implicitSpringDamper>1</implicitSpringDamper>
            <mu1>100000</mu1>
            <mu2>100000</mu2>
            <kp>100000000.0</kp>
            <kd>1.0</kd>
        </gazebo> 

        <link name="gripper_finger2_finger_tip_link">
            <visual>
                <geometry>
                    <mesh filename="package://robotiq_85_description/meshes/visual/robotiq_85_finger_tip_link.dae"/>
                </geometry>
            </visual>
            <collision>
                <geometry>
                    <mesh filename="package://robotiq_85_description/meshes/collision/robotiq_85_finger_tip_link.stl"/>
                </geometry>
            </collision>
            <inertial>
                <mass value="0.019555" />
                <origin xyz="0.0 0.0 0.0" />
                <inertia ixx = "0.000002" ixy = "0.000000" ixz = "0.000000"
                         iyx = "0.000000" iyy = "0.000005" iyz = "0.000000"
                         izx = "0.000000" izy = "0.000000" izz = "0.000006" />
            </inertial>
        </link>
        
        <gazebo reference="gripper_finger2_finger_tip_link">
            <implicitSpringDamper>1</implicitSpringDamper>
            <mu1>100000</mu1>
            <mu2>100000</mu2>
            <kp>100000000.0</kp>
            <kd>1.0</kd>
        </gazebo> 

	<gazebo>
	  <plugin name="gazebo_grasp_fix" filename="libgazebo_grasp_fix.so">
            <arm>
              <arm_name>gripper_arm</arm_name>
              <palm_link>Link4</palm_link>
              <gripper_link>gripper_finger1_finger_tip_link</gripper_link>
              <gripper_link>gripper_finger2_finger_tip_link</gripper_link>
            </arm>
	    <forces_angle_tolerance>100</forces_angle_tolerance>
	    <update_rate>2</update_rate>
	    <grip_count_threshold>1</grip_count_threshold>
	    <max_grip_count>2</max_grip_count>
	    <release_tolerance>0.005</release_tolerance>
	    <disable_collisions_on_attach>true</disable_collisions_on_attach>
	    <contact_topic>__default_topic__</contact_topic>
	  </plugin>
	</gazebo>
    <!-- ############################################################################################################################################################## -->
<transmission name="trans_l1">
        <type>transmission_interface/SimpleTransmission</type>
        <joint name="l1">
            <hardwareInterface>hardware_interface/EffortJointInterface</hardwareInterface>
        </joint>
        <actuator name="l1_motor">
            <hardwareInterface>hardware_interface/EffortJointInterface</hardwareInterface>
            <mechanicalReduction>1</mechanicalReduction>
        </actuator>
    </transmission>
    <transmission name="trans_l2">
        <type>transmission_interface/SimpleTransmission</type>
        <joint name="l2">
            <hardwareInterface>hardware_interface/EffortJointInterface</hardwareInterface>
        </joint>
        <actuator name="l2_motor">
            <hardwareInterface>hardware_interface/EffortJointInterface</hardwareInterface>
            <mechanicalReduction>1</mechanicalReduction>
        </actuator>
    </transmission>
    <transmission name="trans_r1">
        <type>transmission_interface/SimpleTransmission</type>
        <joint name="r1">
            <hardwareInterface>hardware_interface/EffortJointInterface</hardwareInterface>
        </joint>
        <actuator name="r1_motor">
            <hardwareInterface>hardware_interface/EffortJointInterface</hardwareInterface>
            <mechanicalReduction>1</mechanicalReduction>
        </actuator>
    </transmission>
    <transmission name="trans_r2">
        <type>transmission_interface/SimpleTransmission</type>
        <joint name="r2">
            <hardwareInterface>hardware_interface/EffortJointInterface</hardwareInterface>
        </joint>
        <actuator name="r2_motor">
            <hardwareInterface>hardware_interface/EffortJointInterface</hardwareInterface>
            <mechanicalReduction>1</mechanicalReduction>
        </actuator>
    </transmission>
    <transmission name="trans_j1">
        <type>transmission_interface/SimpleTransmission</type>
        <joint name="j1">
            <hardwareInterface>hardware_interface/PositionJointInterface</hardwareInterface>
        </joint>
        <actuator name="j1_motor">
            <hardwareInterface>hardware_interface/PositionJointInterface</hardwareInterface>
            <mechanicalReduction>1</mechanicalReduction>
        </actuator>
    </transmission>
    <transmission name="trans_j2">
        <type>transmission_interface/SimpleTransmission</type>
        <joint name="j2">
            <hardwareInterface>hardware_interface/PositionJointInterface</hardwareInterface>
        </joint>
        <actuator name="j2_motor">
            <hardwareInterface>hardware_interface/PositionJointInterface</hardwareInterface>
            <mechanicalReduction>1</mechanicalReduction>
        </actuator>
    </transmission>
    <transmission name="trans_j3">
        <type>transmission_interface/SimpleTransmission</type>
        <joint name="j3">
            <hardwareInterface>hardware_interface/PositionJointInterface</hardwareInterface>
        </joint>
        <actuator name="j3_motor">
            <hardwareInterface>hardware_interface/PositionJointInterface</hardwareInterface>
            <mechanicalReduction>1</mechanicalReduction>
        </actuator>
    </transmission>
    <transmission name="trans_j4">
        <type>transmission_interface/SimpleTransmission</type>
        <joint name="j4">
            <hardwareInterface>hardware_interface/PositionJointInterface</hardwareInterface>
        </joint>
        <actuator name="j4_motor">
            <hardwareInterface>hardware_interface/PositionJointInterface</hardwareInterface>
            <mechanicalReduction>1</mechanicalReduction>
        </actuator>
    </transmission>
    <transmission name="gripper_finger1_trans">
            <type>transmission_interface/SimpleTransmission</type>
            <joint name="gripper_finger1_joint">
                <hardwareInterface>PositionJointInterface</hardwareInterface>
            </joint>
            <actuator name="gripper_finger1_motor">
                <mechanicalReduction>1</mechanicalReduction>
                <hardwareInterface>PositionJointInterface</hardwareInterface>
            </actuator>
        </transmission>
        
        <gazebo>
                <!-- loading plugin: mimic joints works in gazebo now -->
            <plugin filename="libroboticsgroup_gazebo_mimic_joint_plugin.so" name="mimic_robotiq_85_1">
                <joint>gripper_finger1_joint</joint>
                <mimicJoint>gripper_finger2_joint</mimicJoint>
                <!--multiplier>1.0</multiplier>
                <offset>0.0</offset-->
            </plugin>
            <plugin filename="libroboticsgroup_gazebo_mimic_joint_plugin.so" name="mimic_robotiq_85_2">
                <joint>gripper_finger1_joint</joint>
                <mimicJoint>gripper_finger2_inner_knuckle_joint</mimicJoint>
                <!--multiplier>1.0</multiplier>
                <offset>0.0</offset-->
            </plugin>
            <plugin filename="libroboticsgroup_gazebo_mimic_joint_plugin.so" name="mimic_robotiq_85_3">
                <joint>gripper_finger1_joint</joint>
                <mimicJoint>gripper_finger1_inner_knuckle_joint</mimicJoint>
                <!--multiplier>1.0</multiplier>
                <offset>0.0</offset-->
            </plugin>
            <plugin filename="libroboticsgroup_gazebo_mimic_joint_plugin.so" name="mimic_robotiq_85_4">
                <joint>gripper_finger1_joint</joint>
                <mimicJoint>gripper_finger1_finger_tip_joint</mimicJoint>
                <multiplier>-1.0</multiplier>
                <offset>0.0</offset>
            </plugin>
            <plugin filename="libroboticsgroup_gazebo_mimic_joint_plugin.so" name="mimic_robotiq_85_5">
                <joint>gripper_finger1_joint</joint>
                <mimicJoint>gripper_finger2_finger_tip_joint</mimicJoint>
                <multiplier>-1.0</multiplier>
                <offset>0.0</offset>
            </plugin>
        </gazebo>
    <gazebo>
        <plugin name="gazebo_ros_control" filename="libgazebo_ros_control.so">
            <robotNamespace>/</robotNamespace>
	    <legacyModeNS>true</legacyModeNS>
        </plugin>
    </gazebo>
    <gazebo>
    <plugin name="skid_steer_drive_controller" filename="libgazebo_ros_skid_steer_drive.so">
      <updateRate>40.0</updateRate>
      <leftFrontJoint>l2</leftFrontJoint>  
      <rightFrontJoint>r2</rightFrontJoint>
      <leftRearJoint>l1</leftRearJoint>
      <rightRearJoint>r1</rightRearJoint>
      <wheelSeparation>0.4</wheelSeparation>
      <wheelDiameter>0.2</wheelDiameter>
      <robotBaseFrame>base_link</robotBaseFrame>
      <torque>60</torque>
      <topicName>cmd_vel</topicName>
      
      <commandTopic>cmd_vel</commandTopic>
      <odometryTopic>odom</odometryTopic>
      <odometryFrame>odom</odometryFrame>
      
      <broadcastTF>true</broadcastTF>
   </plugin>
  </gazebo>
    <!-- Kinect sensor plugin -->
    <gazebo reference="camera_link">
    <sensor type="depth" name="camera">
      <always_on>1</always_on>
      <visualize>true</visualize>
      <camera>
        <horizontal_fov>1.047</horizontal_fov>
        <image>
          <width>640</width>
          <height>480</height>
          <format>R8G8B8</format>
        </image>
        <depth_camera>

        </depth_camera>
        <clip>
          <near>0.1</near>
          <far>100</far>
        </clip>
      </camera>
      <plugin name="camera_link" filename="libgazebo_ros_openni_kinect.so">
          <baseline>0.2</baseline>
          <alwaysOn>true</alwaysOn>
          <!-- Keep this zero, update_rate in the parent <sensor> tag
            will control the frame rate. -->
          <updateRate>0.0</updateRate>
          <cameraName>camera_ir</cameraName>
          <imageTopicName>/camera/color/image_raw</imageTopicName>
          <cameraInfoTopicName>/camera/color/camera_info</cameraInfoTopicName>
          <depthImageTopicName>/camera/depth/image_raw</depthImageTopicName>
          <depthImageCameraInfoTopicName>/camera/depth/camera_info</depthImageCameraInfoTopicName>
          <pointCloudTopicName>/camera/depth/points</pointCloudTopicName>
          <frameName>cameraLeft_depth_link</frameName>
          <pointCloudCutoff>0.5</pointCloudCutoff>
          <pointCloudCutoffMax>3.0</pointCloudCutoffMax>
          <distortionK1>0</distortionK1>
          <distortionK2>0</distortionK2>
          <distortionK3>0</distortionK3>
          <distortionT1>0</distortionT1>
          <distortionT2>0</distortionT2>
          <CxPrime>0</CxPrime>
          <Cx>0</Cx>
          <Cy>0</Cy>
          <focalLength>0</focalLength>
          <hackBaseline>0</hackBaseline>
      </plugin>
    </sensor>
  </gazebo>
</robot>

